<?xml version="1.0" ?>
<!-- =================================================================================== -->
<!-- |    This document was autogenerated by xacro from my_robot.urdf.xacro            | -->
<!-- |    EDITING THIS FILE BY HAND IS NOT RECOMMENDED                                 | -->
<!-- =================================================================================== -->
<robot name="my_robot">
  <!-- ===== Differential drive ===== -->
  <gazebo>
    <plugin filename="gz-sim-diff-drive-system" name="gz::sim::systems::DiffDrive">
      <left_joint>left_wheel_joint</left_joint>
      <right_joint>right_wheel_joint</right_joint>
      <wheel_separation>0.26</wheel_separation>
      <wheel_radius>0.05</wheel_radius>
      <odom_publish_frequency>50</odom_publish_frequency>
      <topic>cmd_vel</topic>
      <odom_topic>odom</odom_topic>
      <tf_topic>/tf</tf_topic>
      <frame_id>odom</frame_id>
      <child_frame_id>base_link</child_frame_id>
    </plugin>
  </gazebo>
  <!-- ===== Joint states Gazebo → ROS ===== -->
  <gazebo>
    <plugin filename="gz-sim-joint-state-publisher-system" name="gz::sim::systems::JointStatePublisher">
      <topic>joint_states</topic>
    </plugin>
  </gazebo>
  <!-- ===== Drive wheel surface properties ===== -->
  <!-- mu1/mu2: Coulomb friction coefficients                             -->
  <gazebo reference="left_wheel_link">
    <mu1>1.0</mu1>
    <mu2>1.0</mu2>
  </gazebo>
  <gazebo reference="right_wheel_link">
    <mu1>1.0</mu1>
    <mu2>1.0</mu2>
  </gazebo>
  <!-- ===== Caster: zero friction so it does not resist motion ===== -->
  <gazebo reference="caster_link">
    <mu1>0.0</mu1>
    <mu2>0.0</mu2>
  </gazebo>
  <!-- ===== LiDAR sensor ===== -->
  <gazebo reference="lidar_link">
    <sensor name="lidar_sensor" type="gpu_lidar">
      <always_on>true</always_on>
      <visualize>true</visualize>
      <update_rate>10</update_rate>
      <topic>lidar</topic>
      <gz_frame_id>lidar_link</gz_frame_id>
      <ray>
        <scan>
          <horizontal>
            <samples>360</samples>
            <resolution>1</resolution>
            <min_angle>-3.14159265</min_angle>
            <max_angle>3.14159265</max_angle>
          </horizontal>
          <vertical>
            <samples>1</samples>
            <resolution>0.01</resolution>
            <min_angle>0</min_angle>
            <max_angle>0</max_angle>
          </vertical>
        </scan>
        <range>
          <min>0.1</min>
          <max>10.0</max>
          <resolution>0.01</resolution>
        </range>
      </ray>
    </sensor>
  </gazebo>
  <!-- ===== Materials ===== -->
  <material name="blue">
    <color rgba="0.2 0.4 0.8 1.0"/>
  </material>
  <material name="grey">
    <color rgba="0.5 0.5 0.5 1.0"/>
  </material>
  <material name="green">
    <color rgba="0.9 0.3 0.3 1.0"/>
  </material>
  <!-- ===== Chassis ===== -->
  <!-- Box: 0.30 m (x) × 0.20 m (y) × 0.10 m (z), mass 5 kg             -->
  <!-- Inertia: Ixx=m(y²+z²)/12  Iyy=m(x²+z²)/12  Izz=m(x²+y²)/12      -->
  <link name="base_link">
    <visual>
      <geometry>
        <box size="0.30 0.20 0.10"/>
      </geometry>
      <material name="blue"/>
    </visual>
    <collision>
      <geometry>
        <box size="0.30 0.20 0.10"/>
      </geometry>
    </collision>
    <inertial>
      <mass value="5.0"/>
      <inertia ixx="0.02083" ixy="0.0" ixz="0.0" iyy="0.04167" iyz="0.0" izz="0.05417"/>
    </inertial>
  </link>
  <!-- ===== Left wheel ===== -->
  <!-- Cylinder: r=0.05 m, l=0.03 m, mass 0.5 kg                         -->
  <!-- Joint rotated -π/2 around X so cylinder axis (local Z) → world Y  -->
  <!-- Inertia: Ixx=Iyy=m(3r²+l²)/12  Izz=mr²/2                         -->
  <joint name="left_wheel_joint" type="continuous">
    <parent link="base_link"/>
    <child link="left_wheel_link"/>
    <origin rpy="-1.5708 0.0 0.0" xyz="0.05 0.13 -0.05"/>
    <axis xyz="0 0 1"/>
    <dynamics damping="0.1" friction="0.1"/>
  </joint>
  <link name="left_wheel_link">
    <visual>
      <geometry>
        <cylinder length="0.03" radius="0.05"/>
      </geometry>
      <material name="grey"/>
    </visual>
    <collision>
      <geometry>
        <cylinder length="0.03" radius="0.05"/>
      </geometry>
    </collision>
    <inertial>
      <mass value="0.5"/>
      <inertia ixx="0.00035" ixy="0.0" ixz="0.0" iyy="0.00035" iyz="0.0" izz="0.000625"/>
    </inertial>
  </link>
  <!-- ===== Right wheel ===== -->
  <joint name="right_wheel_joint" type="continuous">
    <parent link="base_link"/>
    <child link="right_wheel_link"/>
    <origin rpy="-1.5708 0.0 0.0" xyz="0.05 -0.13 -0.05"/>
    <axis xyz="0 0 1"/>
    <dynamics damping="0.1" friction="0.1"/>
  </joint>
  <link name="right_wheel_link">
    <visual>
      <geometry>
        <cylinder length="0.03" radius="0.05"/>
      </geometry>
      <material name="grey"/>
    </visual>
    <collision>
      <geometry>
        <cylinder length="0.03" radius="0.05"/>
      </geometry>
    </collision>
    <inertial>
      <mass value="0.5"/>
      <inertia ixx="0.00035" ixy="0.0" ixz="0.0" iyy="0.00035" iyz="0.0" izz="0.000625"/>
    </inertial>
  </link>
  <!-- ===== Caster ===== -->
  <!-- Sphere: r=0.025 m, mass 0.1 kg                                     -->
  <!-- base_link is at body centre = 0.10 m above ground                  -->
  <!-- caster centre at 0.025 m above ground → z = 0.025 - 0.10 = -0.075 -->
  <!-- Inertia: I=2mr²/5                                                  -->
  <joint name="caster_joint" type="fixed">
    <parent link="base_link"/>
    <child link="caster_link"/>
    <origin rpy="0.0 0.0 0.0" xyz="-0.13 0.0 -0.075"/>
  </joint>
  <link name="caster_link">
    <visual>
      <geometry>
        <sphere radius="0.025"/>
      </geometry>
      <material name="grey"/>
    </visual>
    <collision>
      <geometry>
        <sphere radius="0.025"/>
      </geometry>
    </collision>
    <inertial>
      <mass value="0.1"/>
      <inertia ixx="0.000025" ixy="0.0" ixz="0.0" iyy="0.000025" iyz="0.0" izz="0.000025"/>
    </inertial>
  </link>
  <!-- ===== LiDAR link ===== -->
  <!-- Cylinder: r=0.05 m, l=0.04 m, mass 0.1 kg                           -->
  <!-- Ixx=Iyy=m(3r²+l²)/12 ≈ 8.4e-5   Izz=mr²/2 = 1.25e-4               -->
  <link name="lidar_link">
    <visual>
      <geometry>
        <cylinder length="0.04" radius="0.05"/>
      </geometry>
      <material name="green"/>
    </visual>
    <collision>
      <geometry>
        <cylinder length="0.04" radius="0.05"/>
      </geometry>
    </collision>
    <inertial>
      <mass value="0.1"/>
      <inertia ixx="0.000076" ixy="0.0" ixz="0.0" iyy="0.000076" iyz="0.0" izz="0.000125"/>
    </inertial>
  </link>
  <!-- ===== LiDAR joint ===== -->
  <!-- Sensor sits on top of chassis: base_link top face at z=+0.05,        -->
  <!-- lidar cylinder half-height = 0.02 → joint at z=0.07                 -->
  <joint name="lidar_joint" type="fixed">
    <parent link="base_link"/>
    <child link="lidar_link"/>
    <origin rpy="0 0 0" xyz="0 0 0.07"/>
  </joint>
</robot>
